<?xml version="1.0"?>

<robot xmlns:xacro="http://www.ros.org/wiki/xacro" 
 	xmlns:sensor="http://playerstage.sourceforge.net/gazebo/xmlschema/#sensor"
    	xmlns:controller="http://playerstage.sourceforge.net/gazebo/xmlschema/#controller"
    	xmlns:interface="http://playerstage.sourceforge.net/gazebo/xmlschema/#interface"
	name="agrovexr_xacro">

	<xacro:property name="length_wheel" value="0.028" />
  <xacro:property name="radius_wheel" value="0.055" />
  <xacro:macro name="default_inertial" params="mass ixx iyy izz ixy iyz ixz">
               <inertial>
                       <mass value="${mass}" />
                       <inertia ixx="${ixx}" ixy="${ixy}" ixz="${ixz}"
                                iyy="${iyy}" iyz="${iyz}"
                                izz="${izz}" />
               </inertial>
	</xacro:macro>

  <xacro:include filename="$(find agrovex_description)/urdf/agrovex.gazebo" />

	<link name="base_link">
   		<visual>
			<geometry>
      				<mesh filename="package://agrovex_description/meshes/chasis_vex.dae" scale="1 1 1"	/>
     			</geometry>
			<origin	rpy="0 0 1.570796"	xyz="0 0 0.05"	/>
			<material name="white">
				<color rgba="1 1 1 1"/>
			</material>
   		</visual>
		<collision>
			<geometry>
       				<box size="0.3 0.305 0.12"/>
			</geometry>
      <origin rpy="0 0 0"  xyz="0 0 0.06"  />
		</collision>
		<xacro:default_inertial mass="2.09216" ixx="2.304079989" iyy="3.210227493" izz="1.513832891" ixy="0.000201267" iyz="0.000001756" ixz="-0.006896907"   />
 	</link>

 	<link name="wheel_1">
   		<visual>
     			<geometry>
       				<mesh filename="package://agrovex_description/meshes/rueda1_vex.dae" scale="1 1 1"	/>
     			</geometry>
			<origin	rpy="0 0 -1.570796"	xyz="0.02 -0.038 -0.024"	/>
   			<material name="black">
				<color rgba="0 0 0 1"/>
			</material>
		</visual>
		<collision>
			<geometry>
       				<cylinder length="${length_wheel}" radius="${radius_wheel}"/>
			</geometry>
      <origin rpy="0 -1.570796 0" xyz="0.02 0 0"  />
		</collision>
		<xacro:default_inertial mass="0.1061929" ixx="0.00917256595" iyy="0.009174216667" izz="0.01764646301" ixy="0.00000008023" iyz="0.00000003539" ixz="-0.00000006107"/>
 	</link>

 	<link name="wheel_2">
   		<visual>
     			<geometry>
       				<mesh filename="package://agrovex_description/meshes/rueda2_vex.dae" scale="1 1 1" />
     			</geometry>
			    <origin  rpy="0 0 -1.570796" xyz="0.02 -0.038 -0.024"  />
   			<material name="black"/>
   		</visual>
		<collision>
			<geometry>
       				<cylinder length="${length_wheel}" radius="${radius_wheel}"/>
			</geometry>
           <origin rpy="0 -1.570796 0" xyz="0.02 0 0"  />
		</collision>
		<xacro:default_inertial mass="0.1061929" ixx="0.00917256595" iyy="0.009174216667" izz="0.01764646301" ixy="0.00000008023" iyz="0.00000003539" ixz="-0.00000006107"/>

 	</link>
    
 	<link name="wheel_3">
   		<visual>
     			<geometry>
       				<mesh filename="package://agrovex_description/meshes/rueda3_vex.dae" scale="1 1 1" />
     			</geometry>
    			<origin  rpy="0 0 -1.570796" xyz="-0.013 -0.038 -0.024" />
   			<material name="black"/>
   		</visual>
		<collision>
			<geometry>
       				<cylinder length="${length_wheel}" radius="${radius_wheel}"/>
			</geometry>
           <origin rpy="0 1.570796 0" xyz="-0.02 0 0"  />
		</collision>
		<xacro:default_inertial mass="0.1061929" ixx="0.00917256595" iyy="0.009174216667" izz="0.01764646301" ixy="0.00000008023" iyz="0.00000003539" ixz="-0.00000006107"/>
 	</link>

 	<link name="wheel_4">
   		<visual>
     			<geometry>
       				<mesh filename="package://agrovex_description/meshes/rueda4_vex.dae" scale="1 1 1" />
     			</geometry>
			  <origin  rpy="0 0 -1.570796" xyz="-0.013 -0.038 -0.024" />
   			<material name="black"/>
   		</visual>
		<collision>
			<geometry>
       				<cylinder length="${length_wheel}" radius="${radius_wheel}"/>
			</geometry>
           <origin rpy="0 1.570796 0" xyz="-0.02 0 0"  />
		</collision>
		<xacro:default_inertial mass="0.1061929" ixx="0.00917256595" iyy="0.009174216667" izz="0.01764646301" ixy="0.00000008023" iyz="0.00000003539" ixz="-0.00000006107"/>

 	</link>



 <joint name="base_to_wheel1" type="continuous">
      <parent link="base_link"  />
      <child  link="wheel_1"  />
      <origin rpy="0 0 -1.570796"   xyz="0.07925 -0.151 0.027"  />
      <axis xyz="1 0 0" />
 </joint>

 <joint name="base_to_wheel2" type="continuous">
      <parent link="base_link"  />
      <child  link="wheel_2"  />
      <origin rpy="0 0 -1.570796"   xyz="-0.07925 -0.151 0.027" />
      <axis xyz="1 0 0" />
</joint>

 <joint name="base_to_wheel3" type="continuous">
      <parent link="base_link"  />
      <child  link="wheel_3"  />
      <origin rpy="0 0 -1.570796"   xyz="-0.07925 0.151 0.027"  />
      <axis xyz="1 0 0" />
 </joint>

 <joint name="base_to_wheel4" type="continuous">
      <parent link="base_link"  />
      <child  link="wheel_4"  />
      <origin rpy="0 0 -1.570796" xyz="0.07925 0.151 0.027" />
      <axis xyz="1 0 0" />
 </joint>

 

</robot>
