<?xml version="1.0"?>

<robot xmlns:xacro="http://www.ros.org/wiki/xacro" 
 	xmlns:sensor="http://playerstage.sourceforge.net/gazebo/xmlschema/#sensor"
    	xmlns:controller="http://playerstage.sourceforge.net/gazebo/xmlschema/#controller"
    	xmlns:interface="http://playerstage.sourceforge.net/gazebo/xmlschema/#interface"
	name="agrovexr_xacro">


  <xacro:property name="length_wheel" value="0.099" />
  <xacro:property name="radius_wheel" value="0.105" />
  <xacro:property name="camera_link" value="0.05" /> 
  <!--<xacro:macro name="default_inertial" params="mass ixx iyy izz ixy iyz ixz">
               <inertial>
                       <mass value="${mass}" />
                       <inertia ixx="${ixx}" ixy="${ixy}" ixz="${ixz}"
                                iyy="${iyy}" iyz="${iyz}"
                                izz="${izz}" />
               </inertial> -->
	<xacro:macro name="default_inertial" params="mass">
               <inertial>
                       <mass value="${mass}" />
                       <inertia ixx="0.00917256595" ixy="0.00000008023" ixz="-0.00000006107"
                                iyy="0.009174216667" iyz="0.00000003539"
                                izz="0.01764646301" />
               </inertial> 
	</xacro:macro>
	<xacro:property name="camera_link" value="0.05" /> 



<!-- /////////////////////////AGROVEX ESTRUCTURA LINKS////////////////////////  -->

	<link name="base_footprint">
   		<visual>
			<geometry>
      				<box size="0.001 0.001 0.001"/>
     			</geometry>
			<origin rpy="0 0 0" xyz="0 0 0"/>
   		</visual>
		<xacro:default_inertial mass="0.0001"/>
 	</link>
 	<xacro:include filename="$(find agrovex_description)/urdf/agrovex.gazebo" />
 
	<gazebo reference="base_footprint">
		<material>Gazebo/Green</material>
		<turnGravityOff>false</turnGravityOff>
	</gazebo>

	<joint name="base_footprint_joint" type="fixed">
		<origin xyz="0 0 0" />
		<parent link="base_footprint" />
		<child link="base_link" />
	</joint> 

	<link name="base_link">
   		<visual>
			<geometry>
      				<mesh filename="package://agrovex_description/meshes/estructura.dae" scale="1 1 1"	/>
     			</geometry>
			<origin	rpy="0 0 1.570796"	xyz="0 0 0.05"	/>
			<material name="white">
				<color rgba="1 1 1 1"/>
			</material>
   		</visual>
		<collision>
			<geometry>
       				<box size="0.49 0.3 0.12"/>
			</geometry>
      <origin rpy="0 0 0"  xyz="0 0 0.09"  />
		</collision>
   	 <inertial>
    	  <mass value="2.09216" />
     		 <origin xyz="0 0 0" rpy="0 0 0"/>
     		 <inertia ixx="1.0e-06" iyy="1.0e-06" izz="1.0e-06" ixy="0" iyz="0" ixz="0"/> <!-- ixx="2.304079989" iyy="3.210227493" izz="1.513832891" ixy="0.000201267" iyz="0.000001756" ixz="-0.006896907" /> -->
   	 </inertial>
 	</link>

 	<link name="wheel_1">
   		<visual>
     			<geometry>
       				<mesh filename="package://agrovex_description/meshes/wheel_1.dae" scale="1 1 1"	/>
     			</geometry>
			<origin	rpy="0 0 1.570796"	xyz="0 -0.036 -0.06"	/>
   			<material name="black">
				<color rgba="0 0 0 1"/>
			</material>
		</visual>
		<collision>
			<geometry>
       				<cylinder length="${length_wheel}" radius="${radius_wheel}"/>
			</geometry>
      <origin rpy="0 -1.570796 0" xyz="0.075 0 0"  />
		</collision>
		<xacro:default_inertial mass="0.1061929"/> <!-- ixx="0.00917256595" iyy="0.009174216667" izz="0.01764646301" ixy="0.00000008023" iyz="0.00000003539" ixz="-0.00000006107"/> -->
 	</link>

 	<link name="wheel_2">
   		<visual>
     			<geometry>
       				<mesh filename="package://agrovex_description/meshes/wheel_2.dae" scale="1 1 1" />
     			</geometry>
			    <origin  rpy="0 0 1.570796" xyz="0 -0.036 -0.06"  />
   			<material name="black"/>
   		</visual>
		<collision>
			<geometry>
       				<cylinder length="${length_wheel}" radius="${radius_wheel}"/>
			</geometry>
           <origin rpy="0 -1.570796 0" xyz="0.075 0 0"  />
		</collision>
		<xacro:default_inertial mass="0.1061929"/> <!-- ixx="0.00917256595" iyy="0.009174216667" izz="0.01764646301" ixy="0.00000008023" iyz="0.00000003539" ixz="-0.00000006107"/> -->

 	</link>
    
 	<link name="wheel_3">
   		<visual>
     			<geometry>
       				<mesh filename="package://agrovex_description/meshes/wheel_3.dae" scale="1 1 1" />
     			</geometry>
    			<origin  rpy="0 0 -1.570796" xyz="0 0.036 -0.06" />
   			<material name="black"/>
   		</visual>
		<collision>
			<geometry>
       				<cylinder length="${length_wheel}" radius="${radius_wheel}"/>
			</geometry>
           <origin rpy="0 -1.570796 0" xyz="-0.075 0 0"  />
		</collision>
		<xacro:default_inertial mass="0.1061929"/> <!-- ixx="0.00917256595" iyy="0.009174216667" izz="0.01764646301" ixy="0.00000008023" iyz="0.00000003539" ixz="-0.00000006107"/> -->
 	</link>

 	<link name="wheel_4">
   		<visual>
     			<geometry>
       				<mesh filename="package://agrovex_description/meshes/wheel_4.dae" scale="1 1 1" />
     			</geometry>
			  <origin  rpy="0 0 -1.570796" xyz="0 0.036 -0.06" />
   			<material name="black"/>
   		</visual>
		<collision>
			<geometry>
       				<cylinder length="${length_wheel}" radius="${radius_wheel}"/>
			</geometry>
           <origin rpy="0 -1.570796 0" xyz="-0.075 0 0"  />
		</collision>
		<xacro:default_inertial mass="0.1061929"/> <!-- ixx="0.00917256595" iyy="0.009174216667" izz="0.01764646301" ixy="0.00000008023" iyz="0.00000003539" ixz="-0.00000006107"/> -->

 	</link>


<!-- /////////////////////////AGROVEX ESTRUCTURA JOINTS////////////////////////  -->

 <joint name="base_to_wheel1" type="continuous">
      <parent link="base_link"  />
      <child  link="wheel_1"  />
      <origin rpy="0 0 -1.570796"   xyz="0.14725 -0.151 0.068"  />
      <axis xyz="-1 0 0" />
	<limit effort= "100" velocity="100"/>
  	<dynamics damping="0.0" friction="0.0"/>
 </joint>

 <joint name="base_to_wheel2" type="continuous">
      <parent link="base_link"  />
      <child  link="wheel_2"  />
      <origin rpy="0 0 -1.570796"   xyz="-0.14725 -0.151 0.068" />
      <axis xyz="-1 0 0" />
	<limit effort= "100" velocity="100"/>
  	<dynamics damping="0.0" friction="0.0"/>
</joint>

 <joint name="base_to_wheel3" type="continuous">
      <parent link="base_link"  />
      <child  link="wheel_3"  />
      <origin rpy="0 0 -1.570796"   xyz="-0.14725 0.151 0.068"  />
      <axis xyz="-1 0 0" />
	<limit effort= "100" velocity="100"/>
  	<dynamics damping="0.0" friction="0.0"/>
 </joint>

 <joint name="base_to_wheel4" type="continuous">
      <parent link="base_link"  />
      <child  link="wheel_4"  />
      <origin rpy="0 0 -1.570796" xyz="0.14725 0.151 0.068" />
      <axis xyz="-1 0 0" />
	<limit effort= "100" velocity="100"/>
  	<dynamics damping="0.0" friction="0.0"/>
 </joint>


<!-- /////////////////////////AGROVEX ESTRUCTURA TRANSMISSIONS////////////////////////  -->

<transmission name="wheel_m1">
	<type>transmission_interface/SimpleTransmission</type>
	<joint name="base_to_wheel1">
		<hardwareInterface>VelocityJointInterface</hardwareInterface>
	</joint>
	<actuator name="motor1">
		<hardwareInterface>EffortJointInterface</hardwareInterface>
		<mechanicalReduction>1</mechanicalReduction>
	</actuator>
</transmission>

<transmission name="wheel_m2">
	<type>transmission_interface/SimpleTransmission</type>
	<joint name="base_to_wheel2">
		<hardwareInterface>VelocityJointInterface</hardwareInterface>
	</joint>
	<actuator name="motor2">
		<hardwareInterface>EffortJointInterface</hardwareInterface>
		<mechanicalReduction>1</mechanicalReduction>
	</actuator>
</transmission>

<transmission name="wheel_m3">
	<type>transmission_interface/SimpleTransmission</type>
	<joint name="base_to_wheel3">
		<hardwareInterface>VelocityJointInterface</hardwareInterface>
	</joint>
	<actuator name="motor3">
		<hardwareInterface>EffortJointInterface</hardwareInterface>
		<mechanicalReduction>1</mechanicalReduction>
	</actuator>
</transmission>

<transmission name="wheel_m4">
	<type>transmission_interface/SimpleTransmission</type>
	<joint name="base_to_wheel4">
		<hardwareInterface>VelocityJointInterface</hardwareInterface>
	</joint>
	<actuator name="motor4">
		<hardwareInterface>EffortJointInterface</hardwareInterface>
		<mechanicalReduction>1</mechanicalReduction>
	</actuator>
</transmission>



  <!--////////////////// Camera JOINT ////////////////////-->
  <joint name="camera_joint" type="fixed">
    <axis xyz="0 1 0" />
    <origin xyz="0.18 0 0.138" rpy="0 0 0"/>
    <parent link="base_link"/>
    <child link="camera_link"/>
  </joint>

  <!-- ///////////////Camera LINK /////////////////////////7 -->
  <link name="camera_link">
    <collision>
      <origin xyz="0 0 0" rpy="0 0 0"/>
      <geometry>
	<box size="0.009 0.020 0.020"/>
      </geometry>
    </collision>

    <visual>
      <origin xyz="0 0 0" rpy="0 0 0"/>
      <geometry>
	<box size="0.020 0.020 0.020"/>
      </geometry>
      <material name="blac">
	<color rgba="0 0 0 1"/>
      </material>
    </visual>

    <inertial>
      <mass value="1e-5" />
      <origin xyz="0 0 0" rpy="0 0 0"/>
      <inertia ixx="1e-6" ixy="0" ixz="0" iyy="1e-6" iyz="0" izz="1e-6" />
    </inertial>
  </link>

<!--/////////////// Hokuyo JOINT /////////////// -->
  <joint name="hokuyo_joint" type="fixed">
    <origin xyz="0. 0 0.185" rpy="0 0 0"/>
    <parent link="base_link"/>
    <axis xyz="0 1 0" />
    <child link="hokuyo_link"/>
  </joint>

  <!--/////////////// Hokuyo LINK /////////////// -->
  <link name="hokuyo_link">
    <collision>
      <origin xyz="0 0 0" rpy="0 0 0"/>
      <geometry>
	<box size="0.1 0.1 0.1"/>
      </geometry>
    </collision>

    <visual>
      <origin xyz="0 0 0" rpy="0 0 0"/>
      <geometry>
        <mesh filename="package://agrovex_description/meshes/hokuyo.dae"/>
      </geometry>
    </visual>

    <inertial>
      <mass value="1e-5" />
      <origin xyz="0 0 0" rpy="0 0 0"/>
      <inertia ixx="1e-6" ixy="0" ixz="0" iyy="1e-6" iyz="0" izz="1e-6" />
    </inertial>
  </link>
 

  <!--/////////////// Drive controller //////////////-->
<!--<gazebo>
  <plugin name="skid_steer_drive_controller" filename="libgazebo_ros_skid_steer_drive.so">
    <updateRate>100.0</updateRate>
    <robotNamespace>/</robotNamespace>
    <leftFrontJoint>base_to_wheel1</leftFrontJoint>
    <rightFrontJoint>base_to_wheel3</rightFrontJoint>
    <leftRearJoint>base_to_wheel2</leftRearJoint>
    <rightRearJoint>base_to_wheel4</rightRearJoint>
    <wheelSeparation>4</wheelSeparation>
    <wheelDiameter>0.1</wheelDiameter>
    <robotBaseFrame>base_link</robotBaseFrame>
    <torque>1</torque>
    <topicName>cmd_vel</topicName>
    <broadcastTF>0</broadcastTF>
  </plugin>
</gazebo> -->

<gazebo>
  <plugin name="gazebo_ros_control" filename= "libgazebo_ros_control.so">
   <robotNamespace>/</robotNamespace>
  </plugin>
</gazebo>

</robot>
